<?xml version="1.0"?>
<robot name="learm" xmlns:xacro="http://www.ros.org/wiki/xacro">

<xacro:property name="PI" value="3.14159265359" />

<link name="world"/>

  <link name="base_link">
    <inertial>
      <origin xyz="0 0 0.03" rpy="0 0 0"/>
      <mass value="1.0"/>
      <inertia ixx="0.01" ixy="0" ixz="0" iyy="0.01" iyz="0" izz="0.01"/>
    </inertial>
    <visual>
      <geometry>
        <mesh filename="package://fit_description/meshes/base.stl"/>
      </geometry>
    </visual>
    <collision>
      <geometry>
        <cylinder radius="0.05" length="0.06"/>
      </geometry>
    </collision>
  </link>
  <link name="shoulder_link">
    <inertial>
      <origin xyz="0 0 0.014" rpy="0 0 0"/>
      <mass value="0.5"/>
      <inertia ixx="0.001" ixy="0" ixz="0" iyy="0.001" iyz="0" izz="0.001"/>
    </inertial>
    <visual>
      <geometry>
        <mesh filename="package://fit_description/meshes/shoulder.stl"/>
      </geometry>
    </visual>
    <collision>
      <geometry>
        <box size="0.05 0.05 0.028"/>
      </geometry>
    </collision>
  </link>
  <link name="humerus_link">
    <inertial>
      <origin xyz="0 0 0.0525" rpy="0 0 0"/>
      <mass value="0.3"/>
      <inertia ixx="0.001" ixy="0" ixz="0" iyy="0.001" iyz="0" izz="0.001"/>
    </inertial>
    <visual>
      <geometry>
        <mesh filename="package://fit_description/meshes/humerus.stl"/>
      </geometry>
    </visual>
    <collision>
      <geometry>
        <cylinder radius="0.02" length="0.105"/>
      </geometry>
    </collision>
  </link>
  <link name="forearm_link">
    <inertial>
      <origin xyz="0 0 0.045" rpy="0 0 0"/>
      <mass value="0.25"/>
      <inertia ixx="0.001" ixy="0" ixz="0" iyy="0.001" iyz="0" izz="0.0005"/>
    </inertial>
    <visual>
      <geometry>
        <mesh filename="package://fit_description/meshes/forearm.stl"/>
      </geometry>
    </visual>
    <collision>
      <geometry>
        <cylinder radius="0.02" length="0.09"/>
      </geometry>
    </collision>
  </link>
  <link name="wrist_link">
    <inertial>
      <origin xyz="0 0 0.03" rpy="0 0 0"/>
      <mass value="0.2"/>
      <inertia ixx="0.0005" ixy="0" ixz="0" iyy="0.0005" iyz="0" izz="0.0003"/>
    </inertial>
    <visual>
      <origin xyz="0 0 0" rpy="0 0 0"/>
      <geometry>
        <mesh filename="package://fit_description/meshes/wrist.stl"/>
      </geometry>
    </visual>
    <collision>
      <geometry>
        <cylinder radius="0.02" length="0.06"/>
      </geometry>
    </collision>
  </link>
  <link name="hand_link">
    <inertial>
      <origin xyz="0 0 0.015" rpy="0 0 0"/>
      <mass value="0.15"/>
      <inertia ixx="0.0003" ixy="0" ixz="0" iyy="0.0003" iyz="0" izz="0.0002"/>
    </inertial>
    <visual>
      <geometry>
        <mesh filename="package://fit_description/meshes/hand.stl"/>
      </geometry>
    </visual>
    <collision>
      <geometry>
        <box size="0.04 0.04 0.03"/>
      </geometry>
    </collision>
  </link>
  <link name="grip_left_link">
    <inertial>
      <origin xyz="0 0 0.015" rpy="0 0 0"/>
      <mass value="0.05"/>
      <inertia ixx="0.0001" ixy="0" ixz="0" iyy="0.0001" iyz="0" izz="0.0001"/>
    </inertial>
    <visual>
      <geometry>
        <mesh filename="package://fit_description/meshes/carpal-left.stl"/>
      </geometry>
    </visual>
    <collision>
      <geometry>
        <box size="0.01 0.02 0.03"/>
      </geometry>
    </collision>
  </link>
  <link name="grip_right_link">
    <inertial>
      <origin xyz="0 0 0.015" rpy="0 0 0"/>
      <mass value="0.05"/>
      <inertia ixx="0.0001" ixy="0" ixz="0" iyy="0.0001" iyz="0" izz="0.0001"/>
    </inertial>
    <visual>
      <geometry>
        <mesh filename="package://fit_description/meshes/carpal-right.stl"/>
      </geometry>
    </visual>
    <collision>
      <geometry>
        <box size="0.01 0.02 0.03"/>
      </geometry>
    </collision>
  </link>
  <link name="tendon_left_link">
    <inertial>
      <origin xyz="0 0 0.01" rpy="0 0 0"/>
      <mass value="0.02"/>
      <inertia ixx="1e-05" ixy="0" ixz="0" iyy="1e-05" iyz="0" izz="1e-05"/>
    </inertial>
    <visual>
      <geometry>
        <mesh filename="package://fit_description/meshes/tendon.stl"/>
      </geometry>
    </visual>
    <collision>
      <geometry>
        <box size="0.005 0.005 0.02"/>
      </geometry>
    </collision>
  </link>
  <link name="tendon_right_link">
    <inertial>
      <origin xyz="0 0 0.01" rpy="0 0 0"/>
      <mass value="0.02"/>
      <inertia ixx="1e-05" ixy="0" ixz="0" iyy="1e-05" iyz="0" izz="1e-05"/>
    </inertial>
    <visual>
      <geometry>
        <mesh filename="package://fit_description/meshes/tendon.stl"/>
      </geometry>
    </visual>
    <collision>
      <geometry>
        <box size="0.005 0.005 0.02"/>
      </geometry>
    </collision>
  </link>
  <link name="finger_left_link">
    <inertial>
      <origin xyz="0 0 0.01" rpy="0 0 0"/>
      <mass value="0.02"/>
      <inertia ixx="1e-05" ixy="0" ixz="0" iyy="1e-05" iyz="0" izz="1e-05"/>
    </inertial>
    <visual>
      <geometry>
        <mesh filename="package://fit_description/meshes/finger.stl"/>
      </geometry>
    </visual>
    <collision>
      <geometry>
        <box size="0.01 0.01 0.02"/>
      </geometry>
    </collision>
  </link>
  <link name="finger_right_link">
    <inertial>
      <origin xyz="0 0 0.01" rpy="0 0 0"/>
      <mass value="0.02"/>
      <inertia ixx="1e-05" ixy="0" ixz="0" iyy="1e-05" iyz="0" izz="1e-05"/>
    </inertial>
    <visual>
      <origin rpy="0 0 3.14159"/>
      <geometry>
        <mesh filename="package://fit_description/meshes/finger.stl"/>
      </geometry>
    </visual>
    <collision>
      <geometry>
        <box size="0.01 0.01 0.02"/>
      </geometry>
    </collision>
  </link>

   <joint name="virtual_joint" type="fixed">
    <parent link="world"/>
    <child link="base_link"/>
    <origin xyz="0.6 0.4 0.35" rpy="0 0 1.57"/>
  </joint>

  <joint name="shoulder_pan" type="revolute">
    <parent link="base_link"/>
    <child link="shoulder_link"/>
    <origin xyz="0 0 0.059"/>
    <axis xyz="0 0 1"/>
    <limit lower="-1.57" upper="1.57" effort="1000" velocity="0.5"/>
  </joint>
  <joint name="shoulder_lift" type="revolute">
    <parent link="shoulder_link"/>
    <child link="humerus_link"/>
    <origin xyz="-0.010 0 0.028"/>
    <axis xyz="0 1 0"/>
    <limit lower="-1.57" upper="1.57" effort="1000" velocity="0.5"/>
  </joint>
  <joint name="elbow" type="revolute">
    <parent link="humerus_link"/>
    <child link="forearm_link"/>
    <origin xyz="0 0 0.105"/>
    <axis xyz="0 -1 0"/>
    <limit lower="-1.57" upper="1.57" effort="1000" velocity="0.5"/>
  </joint>
  <joint name="wrist_flex" type="revolute">
    <parent link="forearm_link"/>
    <child link="wrist_link"/>
    <origin xyz="0 0 0.090"/>
    <axis xyz="0 -1 0"/>
    <limit lower="-1.57" upper="1.57" effort="1000" velocity="0.5"/>
  </joint>
  <joint name="wrist_roll" type="revolute">
    <parent link="wrist_link"/>
    <child link="hand_link"/>
    <origin xyz="0 0 0.060"/>
    <axis xyz="0 0 1"/>
    <limit lower="-1.57" upper="1.57" effort="1000" velocity="0.5"/>
  </joint>
  <joint name="grip_left" type="revolute">
    <parent link="hand_link"/>
    <child link="grip_left_link"/>
    <origin xyz="0 0.015 0.030" rpy="-1.57 0 0"/>
    <axis xyz="-1 0 0"/>
    <limit lower="-1.57" upper="1.57" effort="1000" velocity="0.5"/>
  </joint>
  <joint name="grip_right" type="revolute">
    <parent link="hand_link"/>
    <child link="grip_right_link"/>
    <origin xyz="0 -0.015 0.030" rpy="1.57 0 0"/>
    <axis xyz="-1 0 0"/>
    <limit lower="-1.57" upper="1.57" effort="1000" velocity="0.5"/>
    <mimic joint="grip_left" multiplier="-1" offset="0"/>
  </joint>
  <joint name="tendon_left" type="revolute">
    <parent link="hand_link"/>
    <child link="tendon_left_link"/>
    <origin xyz="0 0.005 0.050" rpy="-1.57 0 0"/>
    <axis xyz="-1 0 0"/>
    <limit lower="-1.57" upper="1.57" effort="1000" velocity="0.5"/>
    <mimic joint="grip_left" offset="0"/>
  </joint>
  <joint name="tendon_right" type="revolute">
    <parent link="hand_link"/>
    <child link="tendon_right_link"/>
    <origin xyz="0 -0.005 0.050" rpy="1.57 0 0"/>
    <axis xyz="-1 0 0"/>
    <limit lower="-1.57" upper="1.57" effort="1000" velocity="0.5"/>
    <mimic joint="grip_left" multiplier="-1" offset="0"/>
  </joint>
  <joint name="finger_left" type="revolute">
    <parent link="grip_left_link"/>
    <child link="finger_left_link"/>
    <origin xyz="0 0 0.030" rpy="1.57 0 0"/>
    <axis xyz="-1 0 0"/>
    <limit lower="-1.57" upper="1.57" effort="1000" velocity="0.5"/>
    <mimic joint="grip_left" multiplier="-1" offset="0"/>
  </joint>
  <joint name="finger_right" type="revolute">
    <parent link="grip_right_link"/>
    <child link="finger_right_link"/>
    <origin xyz="0 0 0.030" rpy="-1.57 0 0"/>
    <axis xyz="-1 0 0"/>
    <limit lower="-1.57" upper="1.57" effort="1000" velocity="0.5"/>
    <mimic joint="grip_left" offset="0"/>
  </joint>
</robot>
